<mujoco model="fetch">
	<actuator>
		<motor gear="1" ctrllimited="true" ctrlrange="-33.82 33.82" joint="shoulder_pan_joint" name="shoulder_pan" />
		<motor gear="1" ctrllimited="true" ctrlrange="-131.76 131.76" joint="shoulder_lift_joint" name="shoulder_lift" />
		<motor gear="1" ctrllimited="true" ctrlrange="-76.94 76.94" joint="upperarm_roll_joint" name="upperarm_roll" />
		<motor gear="1" ctrllimited="true" ctrlrange="-66.18 66.18" joint="elbow_flex_joint" name="elbow_flex" />
		<motor gear="1" ctrllimited="true" ctrlrange="-29.35 29.35" joint="forearm_roll_joint" name="forearm_roll" />
		<motor gear="1" ctrllimited="true" ctrlrange="-25.70 25.70" joint="wrist_flex_joint" name="wrist_flex" />
		<motor gear="1" ctrllimited="true" ctrlrange="-7.36 7.36" joint="wrist_roll_joint" name="wrist_roll" />
	</actuator>
    <asset>
        <mesh name="base_link" file="meshes/base_link.stl" />
        <mesh name="base_link_collision" file="meshes/base_link_collision.STL" />
        <mesh name="r_wheel_link" file="meshes/r_wheel_link.STL" />
        <mesh name="r_wheel_link_collision" file="meshes/r_wheel_link_collision.STL" />
        <mesh name="l_wheel_link" file="meshes/l_wheel_link.STL" />
        <mesh name="l_wheel_link_collision" file="meshes/l_wheel_link_collision.STL" />
        <mesh name="torso_lift_link" file="meshes/torso_lift_link.stl" />
        <mesh name="torso_lift_link_collision" file="meshes/torso_lift_link_collision.STL" />
        <mesh name="head_pan_link" file="meshes/head_pan_link.stl" />
        <mesh name="head_pan_link_collision" file="meshes/head_pan_link_collision.STL" />
        <mesh name="head_tilt_link" file="meshes/head_tilt_link.stl" />
        <mesh name="head_tilt_link_collision" file="meshes/head_tilt_link_collision.STL" />
        <mesh name="shoulder_pan_link" file="meshes/shoulder_pan_link.stl" />
        <mesh name="shoulder_pan_link_collision" file="meshes/shoulder_pan_link_collision.STL" />
        <mesh name="shoulder_lift_link" file="meshes/shoulder_lift_link.stl" />
        <mesh name="shoulder_lift_link_collision" file="meshes/shoulder_lift_link_collision.STL" />
        <mesh name="upperarm_roll_link" file="meshes/upperarm_roll_link.stl" />
        <mesh name="upperarm_roll_link_collision" file="meshes/upperarm_roll_link_collision.STL" />
        <mesh name="elbow_flex_link" file="meshes/elbow_flex_link.stl" />
        <mesh name="elbow_flex_link_collision" file="meshes/elbow_flex_link_collision.STL" />
        <mesh name="forearm_roll_link" file="meshes/forearm_roll_link.stl" />
        <mesh name="forearm_roll_link_collision" file="meshes/forearm_roll_link_collision.STL" />
        <mesh name="wrist_flex_link" file="meshes/wrist_flex_link.stl" />
        <mesh name="wrist_flex_link_collision" file="meshes/wrist_flex_link_collision.STL" />
        <mesh name="wrist_roll_link" file="meshes/wrist_roll_link.stl" />
        <mesh name="wrist_roll_link_collision" file="meshes/wrist_roll_link_collision.STL" />
        <mesh name="gripper_link" file="meshes/gripper_link.STL" />
        <mesh name="r_gripper_finger_link" file="meshes/r_gripper_finger_link.STL" />
        <mesh name="l_gripper_finger_link" file="meshes/l_gripper_finger_link.STL" />
        <mesh name="bellows_link" file="meshes/bellows_link.STL" />
        <mesh name="bellows_link_collision" file="meshes/bellows_link_collision.STL" />
        <mesh name="estop_link" file="meshes/estop_link.STL" />
        <mesh name="laser_link" file="meshes/laser_link.STL" />
        <mesh name="torso_fixed_link" file="meshes/torso_fixed_link.STL" />
    </asset>
    <worldbody>
        <body name="base" pos="0 0 -0.18">
            <!-- robot view -->
            <camera mode="fixed" name="robotview" pos="1.0 0 0.4" quat="0.653 0.271 0.271 0.653"/>
            <inertial diaginertia="0 0 0" mass="0" pos="0 0 0"/>
            <!-- mount attached here -->
            <geom euler="1.57 0 0" type="mesh" contype="0" conaffinity="0" group="1" rgba="0.356 0.361 0.376 1" mesh="base_link" />
            <geom euler="1.57 0 0" type="mesh" rgba="0.356 0.361 0.376 1" mesh="base_link_collision" />
            <geom pos="-0.12465 0.23892 0.31127" quat="0.707105 0.707108 0 0" type="mesh" contype="0" conaffinity="0" group="1" rgba="0.8 0 0 1" mesh="estop_link" />
            <geom pos="-0.12465 0.23892 0.31127" quat="0.707105 0.707108 0 0" type="mesh" rgba="0.8 0 0 1" mesh="estop_link" />
            <geom pos="0.235 0 0.2878" quat="0 1 0 0" type="mesh" contype="0" conaffinity="0" group="1" rgba="0.792157 0.819608 0.933333 1" mesh="laser_link" />
            <geom pos="0.235 0 0.2878" quat="0 1 0 0" type="mesh" rgba="0.792157 0.819608 0.933333 1" mesh="laser_link" />
            <!--geom euler="1.57 0 0" pos="-0.086875 0 0.377425" type="mesh" contype="0" conaffinity="0" group="1" rgba="0.086 0.506 0.767 1" mesh="torso_fixed_link" />
            <geom euler="1.57 0 0" pos="-0.086875 0 0.377425" type="mesh" rgba="0.086 0.506 0.767 1" mesh="torso_fixed_link" /-->
            <body name="r_wheel_link" pos="0.0012914 -0.18738 0.055325">
                <inertial pos="0 0 0" quat="0.707107 0 0 0.707107" mass="4.3542" diaginertia="0.005 0.0045 0.0045" />
                <!--joint name="r_wheel_joint" pos="0 0 0" axis="0 1 0" /-->
                <geom euler="1.57 0 0" type="mesh" contype="0" conaffinity="0" group="1" rgba="0.086 0.506 0.767 1" mesh="r_wheel_link" />
                <geom euler="1.57 0 0" type="mesh" rgba="0.086 0.506 0.767 1" mesh="r_wheel_link_collision" />
            </body>
            <body name="l_wheel_link" pos="0.0012914 0.18738 0.055325">
                <inertial pos="0 0 0" quat="0.707107 0 0 0.707107" mass="4.3542" diaginertia="0.005 0.0045 0.0045" />
                <!--joint name="l_wheel_joint" pos="0 0 0" axis="0 1 0" /-->
                <geom euler="1.57 0 0" type="mesh" contype="0" conaffinity="0" group="1" rgba="0.086 0.506 0.767 1" mesh="l_wheel_link" />
                <geom euler="1.57 0 0" type="mesh" rgba="0.086 0.506 0.767 1" mesh="l_wheel_link_collision" />
            </body>
            <body name="torso_lift_link" pos="-0.086875 0 0.37743">
                <inertial pos="-0.0013 -0.0009 0.2935" quat="0.999265 -0.000621225 0.0335581 0.0184986" mass="10.7796" diaginertia="0.33649 0.3354 0.09431" />
                <!--joint name="torso_lift_joint" pos="0 0 0" axis="0 0 1" type="slide" limited="true" range="0 0.38615" damping="100" /-->
                <geom euler="1.57 0 0" type="mesh" contype="0" conaffinity="0" group="1" rgba="1 1 1 1" mesh="torso_lift_link" />
                <geom euler="1.57 0 0" type="mesh" rgba="1 1 1 1" mesh="torso_lift_link_collision" />
                <body name="head_pan_link" pos="0.053125 0 0.603001">
                    <inertial pos="0.0321 0.0161 0.039" quat="0.514814 0.545129 -0.452957 0.482318" mass="2.2556" diaginertia="0.0184878 0.0128242 0.00948808" />
                    <!--joint name="head_pan_joint" pos="0 0 0" axis="0 0 1" limited="true" range="-1.57 1.57" /-->
                    <geom euler="1.57 0 0" type="mesh" contype="0" conaffinity="0" group="1" rgba="0.356 0.361 0.376 1" mesh="head_pan_link" />
                    <geom euler="1.57 0 0" type="mesh" rgba="0.356 0.361 0.376 1" mesh="head_pan_link_collision" />
                    <body name="head_tilt_link" pos="0.14253 0 0.057999">
                        <inertial pos="0.0081 0.0025 0.0113" quat="0.645806 0.659961 -0.274048 0.268857" mass="0.9087" diaginertia="0.00630102 0.00590111 0.00139787" />
                        <!--joint name="head_tilt_joint" pos="0 0 0" axis="0 1 0" limited="true" range="-0.76 1.45" /-->
                        <geom euler="1.57 0 0" type="mesh" contype="0" conaffinity="0" group="1" rgba="0.086 0.506 0.767 1" mesh="head_tilt_link" />
                        <geom euler="1.57 0 0" type="mesh" rgba="0.086 0.506 0.767 1" mesh="head_tilt_link_collision" />
                    </body>
                </body>
                <body name="shoulder_pan_link" pos="0.119525 0 0.31858" euler="0 0 0">
                    <inertial pos="0.0927 -0.0056 0.0564" quat="-0.136432 0.762398 -0.156155 0.612985" mass="2.5587" diaginertia="0.00896934 0.00864854 0.00408212" />
                    <joint name="shoulder_pan_joint" pos="0 0 0" axis="0 0 1" limited="true" range="-1.6056 1.6056" damping="1" />
                    <geom euler="1.57 0 0" type="mesh" contype="0" conaffinity="0" group="1" rgba="1 1 1 1" mesh="shoulder_pan_link" />
                    <geom euler="1.57 0 0" type="mesh" rgba="1 1 1 1" mesh="shoulder_pan_link_collision" />
                    <body name="shoulder_lift_link" pos="0.117 0 0.06">
                        <inertial pos="0.1432 0.0072 -0.0001" quat="0.438152 0.438152 0.554998 0.554998" mass="2.6615" diaginertia="0.0116011 0.0112 0.00229892" />
                        <joint name="shoulder_lift_joint" pos="0 0 0" axis="0 1 0" limited="true" range="-1.221 1.518" damping="1" />
                        <geom euler="1.57 0 0" type="mesh" contype="0" conaffinity="0" group="1" rgba="0.086 0.506 0.767 1" mesh="shoulder_lift_link" />
                        <geom euler="1.57 0 0" type="mesh" rgba="0.086 0.506 0.767 1" mesh="shoulder_lift_link_collision" />
                        <body name="upperarm_roll_link" pos="0.219 0 0">
                            <inertial pos="0.1165 0.0014 0" quat="-0.0135706 0.706977 0.0135706 0.706977" mass="2.3311" diaginertia="0.0047 0.00450384 0.00189616" />
                            <joint name="upperarm_roll_joint" pos="0 0 0" axis="1 0 0" damping="5" />
                            <geom euler="1.57 0 0" type="mesh" contype="0" conaffinity="0" group="1" rgba="1 1 1 1" mesh="upperarm_roll_link" />
                            <geom euler="1.57 0 0" type="mesh" rgba="1 1 1 1" mesh="upperarm_roll_link_collision" />
                            <body name="elbow_flex_link" pos="0.133 0 0">
                                <inertial pos="0.1279 0.0073 0" quat="0.43318 0.43318 0.558888 0.558888" mass="2.1299" diaginertia="0.0086121 0.0084 0.0019879" />
                                <joint name="elbow_flex_joint" pos="0 0 0" axis="0 1 0" limited="true" range="-2.251 2.251" damping="1" />
                                <geom euler="1.57 0 0" type="mesh" contype="0" conaffinity="0" group="1" rgba="0.086 0.506 0.767 1" mesh="elbow_flex_link" />
                                <geom euler="1.57 0 0" type="mesh" rgba="0.086 0.506 0.767 1" mesh="elbow_flex_link_collision" />
                                <body name="forearm_roll_link" pos="0.197 0 0">
                                    <inertial pos="0.1097 -0.0266 0" quat="-0.0714533 0.703487 0.0714533 0.703487" mass="1.6563" diaginertia="0.0035 0.00306158 0.00153842" />
                                    <joint name="forearm_roll_joint" pos="0 0 0" axis="1 0 0" damping="5" />
                                    <geom euler="1.57 0 0" type="mesh" contype="0" conaffinity="0" group="1" rgba="1 1 1 1" mesh="forearm_roll_link" />
                                    <geom euler="1.57 0 0" type="mesh" rgba="1 1 1 1" mesh="forearm_roll_link_collision" />
                                    <body name="wrist_flex_link" pos="0.1245 0 0">
                                        <inertial pos="0.0882 0.0009 -0.0001" quat="0.4895 0.4895 0.510284 0.510284" mass="1.725" diaginertia="0.00420416 0.0042 0.00179584" />
                                        <joint name="wrist_flex_joint" pos="0 0 0" axis="0 1 0" limited="true" range="-2.16 2.16" damping="1" />
                                        <geom euler="1.57 0 0" type="mesh" contype="0" conaffinity="0" group="1" rgba="0.086 0.506 0.767 1" mesh="wrist_flex_link" />
                                        <geom euler="1.57 0 0" type="mesh" rgba="0.086 0.506 0.767 1" mesh="wrist_flex_link_collision" />
                                        <body name="wrist_roll_link" pos="0.1385 0 0">
                                            <inertial pos="0.0709657 -5.90417e-05 -0.00157713" quat="0.00123263 0.709764 -0.00131059 0.704437" mass="1.6529" diaginertia="0.00305731 0.00255748 0.0014002" />
                                            <joint name="wrist_roll_joint" pos="0 0 0" axis="1 0 0" damping="5" />
                                            <geom euler="1.57 0 0" type="mesh" contype="0" conaffinity="0" group="1" rgba="1 1 1 1" mesh="wrist_roll_link" />
                                            <geom euler="1.57 0 0" type="mesh" rgba="1 1 1 1" mesh="wrist_roll_link_collision" />
                                            <body name="right_hand" pos="0 0 0.0" quat="1.57 1.57 1.57 1.57">
                                                <!-- This sites were added for visualization. They are all standardized between models-->
                                                <!-- Position mimics the gripper attachment point (right_hand) -->
                                                <!--  Y-axis should be perpendicular to grasping motion, and Z-axis should point out of the robot eef -->
                                                <site name="ee" pos="0 0 0" size="0.01 0.01 0.01" rgba="0 0 1 1" type="sphere" group="1"/>
                                                <site name="ee_x" pos="0 0 0" size="0.005 .1"  quat="0.707105 0.707108 0 0 " rgba="1 0 0 0" type="cylinder" group="1"/>
                                                <site name="ee_z" pos="0 0 0" size="0.005 .1" quat="0.707105 0 0 0.707108" rgba="0 0 1 0" type="cylinder" group="1"/>
                                                <site name="ee_y" pos="0 0 0" size="0.005 .1" quat="0.707105 0 0.707108 0 " rgba="0 1 0 0" type="cylinder" group="1"/>
                                                <!-- This camera points out from the eef. -->
                                                <camera mode="fixed" name="eye_in_hand" pos="0.05 0 0" quat="0 0.707108 0.707108 0" fovy="75"/>
                                                <!-- to add gripper -->
                                            </body>
                                        </body>
                                    </body>
                                </body>
                            </body>
                        </body>
                    </body>
                </body>
                <body name="bellows_link" pos="0 0 0">
                    <inertial pos="0.019132 0 -0.134862" quat="1 0 1.66507e-05 0" mass="0.169374" diaginertia="0.00331159 0.00174447 0.00169418" />
                    <!--joint name="bellows_joint" pos="0 0 0" axis="0 0 -1" type="slide" limited="true" range="0 0.4" /-->
                    <geom type="mesh" contype="0" conaffinity="0" group="1" rgba="0 0 0 1" mesh="bellows_link" />
                    <geom type="mesh" rgba="0 0 0 1" mesh="bellows_link_collision" />
                </body>
            </body>
        </body>
    </worldbody>
</mujoco>
